[2024-11-04T06:00:03.127+0000] {local_task_job_runner.py:120} INFO - ::group::Pre task execution logs
[2024-11-04T06:00:03.192+0000] {taskinstance.py:2076} INFO - Dependencies all met for dep_context=non-requeueable deps ti=<TaskInstance: SessionSummaryWithConstraintsCheck.create_joined_table scheduled__2024-11-03T06:00:00+00:00 [queued]>
[2024-11-04T06:00:03.205+0000] {taskinstance.py:2076} INFO - Dependencies all met for dep_context=requeueable deps ti=<TaskInstance: SessionSummaryWithConstraintsCheck.create_joined_table scheduled__2024-11-03T06:00:00+00:00 [queued]>
[2024-11-04T06:00:03.207+0000] {taskinstance.py:2306} INFO - Starting attempt 1 of 1
[2024-11-04T06:00:03.228+0000] {taskinstance.py:2330} INFO - Executing <Task(_PythonDecoratedOperator): create_joined_table> on 2024-11-03 06:00:00+00:00
[2024-11-04T06:00:03.248+0000] {standard_task_runner.py:90} INFO - Running: ['***', 'tasks', 'run', 'SessionSummaryWithConstraintsCheck', 'create_joined_table', 'scheduled__2024-11-03T06:00:00+00:00', '--job-id', '54', '--raw', '--subdir', 'DAGS_FOLDER/CTAS_Summary_DAG_with_constraints.py', '--cfg-path', '/tmp/tmp9s_fx5hu']
[2024-11-04T06:00:03.255+0000] {standard_task_runner.py:91} INFO - Job 54: Subtask create_joined_table
[2024-11-04T06:00:03.261+0000] {logging_mixin.py:188} WARNING - /home/***/.local/lib/python3.12/site-packages/***/task/task_runner/standard_task_runner.py:61 DeprecationWarning: This process (pid=59273) is multi-threaded, use of fork() may lead to deadlocks in the child.
[2024-11-04T06:00:03.263+0000] {standard_task_runner.py:63} INFO - Started process 59280 to run task
[2024-11-04T06:00:03.361+0000] {task_command.py:426} INFO - Running <TaskInstance: SessionSummaryWithConstraintsCheck.create_joined_table scheduled__2024-11-03T06:00:00+00:00 [running]> on host 4a25c42f06c7
[2024-11-04T06:00:03.543+0000] {taskinstance.py:2648} INFO - Exporting env vars: AIRFLOW_CTX_DAG_OWNER='***' AIRFLOW_CTX_DAG_ID='SessionSummaryWithConstraintsCheck' AIRFLOW_CTX_TASK_ID='create_joined_table' AIRFLOW_CTX_EXECUTION_DATE='2024-11-03T06:00:00+00:00' AIRFLOW_CTX_TRY_NUMBER='1' AIRFLOW_CTX_DAG_RUN_ID='scheduled__2024-11-03T06:00:00+00:00'
[2024-11-04T06:00:03.546+0000] {taskinstance.py:430} INFO - ::endgroup::
[2024-11-04T06:00:03.567+0000] {base.py:84} INFO - Using connection ID 'snowflake_conn' for task execution.
[2024-11-04T06:00:03.570+0000] {connection.py:399} INFO - Snowflake Connector for Python Version: 3.10.0, Python Version: 3.12.3, Platform: Linux-5.15.153.1-microsoft-standard-WSL2-x86_64-with-glibc2.36
[2024-11-04T06:00:03.572+0000] {connection.py:1239} INFO - This connection is in OCSP Fail Open Mode. TLS Certificates would be checked for validity and revocation status. Any other Certificate Revocation related exceptions or OCSP Responder failures would be disregarded in favor of connectivity.
[2024-11-04T06:00:05.377+0000] {connection.py:762} INFO - closed
[2024-11-04T06:00:05.436+0000] {connection.py:768} INFO - No async queries seem to be running, deleting session
[2024-11-04T06:00:05.521+0000] {taskinstance.py:441} INFO - ::group::Post task execution logs
[2024-11-04T06:00:05.523+0000] {taskinstance.py:2905} ERROR - Task failed with exception
Traceback (most recent call last):
  File "/home/airflow/.local/lib/python3.12/site-packages/airflow/models/taskinstance.py", line 465, in _execute_task
    result = _execute_callable(context=context, **execute_callable_kwargs)
             ^^^^^^^^^^^^^^^^^^^^^^^^^^^^^^^^^^^^^^^^^^^^^^^^^^^^^^^^^^^^^
  File "/home/airflow/.local/lib/python3.12/site-packages/airflow/models/taskinstance.py", line 432, in _execute_callable
    return execute_callable(context=context, **execute_callable_kwargs)
           ^^^^^^^^^^^^^^^^^^^^^^^^^^^^^^^^^^^^^^^^^^^^^^^^^^^^^^^^^^^^
  File "/home/airflow/.local/lib/python3.12/site-packages/airflow/models/baseoperator.py", line 400, in wrapper
    return func(self, *args, **kwargs)
           ^^^^^^^^^^^^^^^^^^^^^^^^^^^
  File "/home/airflow/.local/lib/python3.12/site-packages/airflow/decorators/base.py", line 265, in execute
    return_value = super().execute(context)
                   ^^^^^^^^^^^^^^^^^^^^^^^^
  File "/home/airflow/.local/lib/python3.12/site-packages/airflow/models/baseoperator.py", line 400, in wrapper
    return func(self, *args, **kwargs)
           ^^^^^^^^^^^^^^^^^^^^^^^^^^^
  File "/home/airflow/.local/lib/python3.12/site-packages/airflow/operators/python.py", line 235, in execute
    return_value = self.execute_callable()
                   ^^^^^^^^^^^^^^^^^^^^^^^
  File "/home/airflow/.local/lib/python3.12/site-packages/airflow/operators/python.py", line 252, in execute_callable
    return self.python_callable(*self.op_args, **self.op_kwargs)
           ^^^^^^^^^^^^^^^^^^^^^^^^^^^^^^^^^^^^^^^^^^^^^^^^^^^^^
  File "/opt/airflow/dags/CTAS_Summary_DAG_with_constraints.py", line 23, in create_joined_table
    cur.execute(f"""
  File "/home/airflow/.local/lib/python3.12/site-packages/snowflake/connector/cursor.py", line 1080, in execute
    Error.errorhandler_wrapper(self.connection, self, error_class, errvalue)
  File "/home/airflow/.local/lib/python3.12/site-packages/snowflake/connector/errors.py", line 290, in errorhandler_wrapper
    handed_over = Error.hand_to_other_handler(
                  ^^^^^^^^^^^^^^^^^^^^^^^^^^^^
  File "/home/airflow/.local/lib/python3.12/site-packages/snowflake/connector/errors.py", line 345, in hand_to_other_handler
    cursor.errorhandler(connection, cursor, error_class, error_value)
  File "/home/airflow/.local/lib/python3.12/site-packages/snowflake/connector/errors.py", line 221, in default_errorhandler
    raise error_class(
snowflake.connector.errors.ProgrammingError: 001998 (42710): 01b823c8-0004-1d17-0001-95fb0003603a: SQL compilation error:
Object 'SESSION_SUMMARY' already exists as VIEW
[2024-11-04T06:00:05.541+0000] {taskinstance.py:1206} INFO - Marking task as FAILED. dag_id=SessionSummaryWithConstraintsCheck, task_id=create_joined_table, run_id=scheduled__2024-11-03T06:00:00+00:00, execution_date=20241103T060000, start_date=20241104T060003, end_date=20241104T060005
[2024-11-04T06:00:05.570+0000] {standard_task_runner.py:110} ERROR - Failed to execute job 54 for task create_joined_table (001998 (42710): 01b823c8-0004-1d17-0001-95fb0003603a: SQL compilation error:
Object 'SESSION_SUMMARY' already exists as VIEW; 59280)
[2024-11-04T06:00:05.613+0000] {local_task_job_runner.py:240} INFO - Task exited with return code 1
[2024-11-04T06:00:05.636+0000] {local_task_job_runner.py:222} INFO - ::endgroup::
