[2024-11-12T05:16:27.037+0000] {local_task_job_runner.py:120} INFO - ::group::Pre task execution logs
[2024-11-12T05:16:27.068+0000] {taskinstance.py:2076} INFO - Dependencies all met for dep_context=non-requeueable deps ti=<TaskInstance: dbt_stock_analysis_dag.dbt_run manual__2024-11-12T05:11:25.250277+00:00 [queued]>
[2024-11-12T05:16:27.079+0000] {taskinstance.py:2076} INFO - Dependencies all met for dep_context=requeueable deps ti=<TaskInstance: dbt_stock_analysis_dag.dbt_run manual__2024-11-12T05:11:25.250277+00:00 [queued]>
[2024-11-12T05:16:27.083+0000] {taskinstance.py:2306} INFO - Starting attempt 2 of 2
[2024-11-12T05:16:27.110+0000] {taskinstance.py:2330} INFO - Executing <Task(BashOperator): dbt_run> on 2024-11-12 05:11:25.250277+00:00
[2024-11-12T05:16:27.117+0000] {standard_task_runner.py:90} INFO - Running: ['***', 'tasks', 'run', 'dbt_stock_analysis_dag', 'dbt_run', 'manual__2024-11-12T05:11:25.250277+00:00', '--job-id', '172', '--raw', '--subdir', 'DAGS_FOLDER/DAG for dbt.py', '--cfg-path', '/tmp/tmphotnv8mw']
[2024-11-12T05:16:27.120+0000] {standard_task_runner.py:91} INFO - Job 172: Subtask dbt_run
[2024-11-12T05:16:27.125+0000] {logging_mixin.py:188} WARNING - /home/***/.local/lib/python3.12/site-packages/***/task/task_runner/standard_task_runner.py:61 DeprecationWarning: This process (pid=642) is multi-threaded, use of fork() may lead to deadlocks in the child.
[2024-11-12T05:16:27.131+0000] {standard_task_runner.py:63} INFO - Started process 643 to run task
[2024-11-12T05:16:27.178+0000] {task_command.py:426} INFO - Running <TaskInstance: dbt_stock_analysis_dag.dbt_run manual__2024-11-12T05:11:25.250277+00:00 [running]> on host f3d2ff879b5a
[2024-11-12T05:16:27.356+0000] {taskinstance.py:2648} INFO - Exporting env vars: AIRFLOW_CTX_DAG_OWNER='Utkarsh Tripathi' AIRFLOW_CTX_DAG_ID='dbt_stock_analysis_dag' AIRFLOW_CTX_TASK_ID='dbt_run' AIRFLOW_CTX_EXECUTION_DATE='2024-11-12T05:11:25.250277+00:00' AIRFLOW_CTX_TRY_NUMBER='2' AIRFLOW_CTX_DAG_RUN_ID='manual__2024-11-12T05:11:25.250277+00:00'
[2024-11-12T05:16:27.358+0000] {taskinstance.py:430} INFO - ::endgroup::
[2024-11-12T05:16:27.385+0000] {subprocess.py:63} INFO - Tmp dir root location: /tmp
[2024-11-12T05:16:27.387+0000] {subprocess.py:75} INFO - Running command: ['/usr/bin/bash', '-c', '/home/***/.local/bin/dbt run --profiles-dir /opt/***/dbt --project-dir /opt/***/dbt']
[2024-11-12T05:16:27.395+0000] {subprocess.py:86} INFO - Output:
[2024-11-12T05:16:27.397+0000] {subprocess.py:93} INFO - /usr/bin/bash: line 1: /home/***/.local/bin/dbt: No such file or directory
[2024-11-12T05:16:27.398+0000] {subprocess.py:97} INFO - Command exited with return code 127
[2024-11-12T05:16:27.400+0000] {taskinstance.py:441} INFO - ::group::Post task execution logs
[2024-11-12T05:16:27.412+0000] {taskinstance.py:2905} ERROR - Task failed with exception
Traceback (most recent call last):
  File "/home/airflow/.local/lib/python3.12/site-packages/airflow/models/taskinstance.py", line 465, in _execute_task
    result = _execute_callable(context=context, **execute_callable_kwargs)
             ^^^^^^^^^^^^^^^^^^^^^^^^^^^^^^^^^^^^^^^^^^^^^^^^^^^^^^^^^^^^^
  File "/home/airflow/.local/lib/python3.12/site-packages/airflow/models/taskinstance.py", line 432, in _execute_callable
    return execute_callable(context=context, **execute_callable_kwargs)
           ^^^^^^^^^^^^^^^^^^^^^^^^^^^^^^^^^^^^^^^^^^^^^^^^^^^^^^^^^^^^
  File "/home/airflow/.local/lib/python3.12/site-packages/airflow/models/baseoperator.py", line 400, in wrapper
    return func(self, *args, **kwargs)
           ^^^^^^^^^^^^^^^^^^^^^^^^^^^
  File "/home/airflow/.local/lib/python3.12/site-packages/airflow/operators/bash.py", line 243, in execute
    raise AirflowException(
airflow.exceptions.AirflowException: Bash command failed. The command returned a non-zero exit code 127.
[2024-11-12T05:16:27.421+0000] {taskinstance.py:1206} INFO - Marking task as FAILED. dag_id=dbt_stock_analysis_dag, task_id=dbt_run, run_id=manual__2024-11-12T05:11:25.250277+00:00, execution_date=20241112T051125, start_date=20241112T051627, end_date=20241112T051627
[2024-11-12T05:16:27.444+0000] {standard_task_runner.py:110} ERROR - Failed to execute job 172 for task dbt_run (Bash command failed. The command returned a non-zero exit code 127.; 643)
[2024-11-12T05:16:27.467+0000] {local_task_job_runner.py:240} INFO - Task exited with return code 1
[2024-11-12T05:16:27.494+0000] {taskinstance.py:3498} INFO - 0 downstream tasks scheduled from follow-on schedule check
[2024-11-12T05:16:27.503+0000] {local_task_job_runner.py:222} INFO - ::endgroup::
