[2024-11-12T05:11:26.114+0000] {local_task_job_runner.py:120} INFO - ::group::Pre task execution logs
[2024-11-12T05:11:26.192+0000] {taskinstance.py:2076} INFO - Dependencies all met for dep_context=non-requeueable deps ti=<TaskInstance: dbt_stock_analysis_dag.dbt_run manual__2024-11-12T05:11:25.250277+00:00 [queued]>
[2024-11-12T05:11:26.226+0000] {taskinstance.py:2076} INFO - Dependencies all met for dep_context=requeueable deps ti=<TaskInstance: dbt_stock_analysis_dag.dbt_run manual__2024-11-12T05:11:25.250277+00:00 [queued]>
[2024-11-12T05:11:26.229+0000] {taskinstance.py:2306} INFO - Starting attempt 1 of 2
[2024-11-12T05:11:26.269+0000] {taskinstance.py:2330} INFO - Executing <Task(BashOperator): dbt_run> on 2024-11-12 05:11:25.250277+00:00
[2024-11-12T05:11:26.279+0000] {standard_task_runner.py:90} INFO - Running: ['***', 'tasks', 'run', 'dbt_stock_analysis_dag', 'dbt_run', 'manual__2024-11-12T05:11:25.250277+00:00', '--job-id', '170', '--raw', '--subdir', 'DAGS_FOLDER/DAG for dbt.py', '--cfg-path', '/tmp/tmpmp_u9wgb']
[2024-11-12T05:11:26.282+0000] {standard_task_runner.py:91} INFO - Job 170: Subtask dbt_run
[2024-11-12T05:11:26.284+0000] {logging_mixin.py:188} WARNING - /home/***/.local/lib/python3.12/site-packages/***/task/task_runner/standard_task_runner.py:61 DeprecationWarning: This process (pid=306) is multi-threaded, use of fork() may lead to deadlocks in the child.
[2024-11-12T05:11:26.287+0000] {standard_task_runner.py:63} INFO - Started process 307 to run task
[2024-11-12T05:11:26.373+0000] {task_command.py:426} INFO - Running <TaskInstance: dbt_stock_analysis_dag.dbt_run manual__2024-11-12T05:11:25.250277+00:00 [running]> on host f3d2ff879b5a
[2024-11-12T05:11:26.599+0000] {taskinstance.py:2648} INFO - Exporting env vars: AIRFLOW_CTX_DAG_OWNER='Utkarsh Tripathi' AIRFLOW_CTX_DAG_ID='dbt_stock_analysis_dag' AIRFLOW_CTX_TASK_ID='dbt_run' AIRFLOW_CTX_EXECUTION_DATE='2024-11-12T05:11:25.250277+00:00' AIRFLOW_CTX_TRY_NUMBER='1' AIRFLOW_CTX_DAG_RUN_ID='manual__2024-11-12T05:11:25.250277+00:00'
[2024-11-12T05:11:26.601+0000] {taskinstance.py:430} INFO - ::endgroup::
[2024-11-12T05:11:26.625+0000] {subprocess.py:63} INFO - Tmp dir root location: /tmp
[2024-11-12T05:11:26.626+0000] {subprocess.py:75} INFO - Running command: ['/usr/bin/bash', '-c', '/home/***/.local/bin/dbt run --profiles-dir /opt/***/dbt --project-dir /opt/***/dbt']
[2024-11-12T05:11:26.639+0000] {subprocess.py:86} INFO - Output:
[2024-11-12T05:11:26.640+0000] {subprocess.py:93} INFO - /usr/bin/bash: line 1: /home/***/.local/bin/dbt: No such file or directory
[2024-11-12T05:11:26.641+0000] {subprocess.py:97} INFO - Command exited with return code 127
[2024-11-12T05:11:26.643+0000] {taskinstance.py:441} INFO - ::group::Post task execution logs
[2024-11-12T05:11:26.655+0000] {taskinstance.py:2905} ERROR - Task failed with exception
Traceback (most recent call last):
  File "/home/airflow/.local/lib/python3.12/site-packages/airflow/models/taskinstance.py", line 465, in _execute_task
    result = _execute_callable(context=context, **execute_callable_kwargs)
             ^^^^^^^^^^^^^^^^^^^^^^^^^^^^^^^^^^^^^^^^^^^^^^^^^^^^^^^^^^^^^
  File "/home/airflow/.local/lib/python3.12/site-packages/airflow/models/taskinstance.py", line 432, in _execute_callable
    return execute_callable(context=context, **execute_callable_kwargs)
           ^^^^^^^^^^^^^^^^^^^^^^^^^^^^^^^^^^^^^^^^^^^^^^^^^^^^^^^^^^^^
  File "/home/airflow/.local/lib/python3.12/site-packages/airflow/models/baseoperator.py", line 400, in wrapper
    return func(self, *args, **kwargs)
           ^^^^^^^^^^^^^^^^^^^^^^^^^^^
  File "/home/airflow/.local/lib/python3.12/site-packages/airflow/operators/bash.py", line 243, in execute
    raise AirflowException(
airflow.exceptions.AirflowException: Bash command failed. The command returned a non-zero exit code 127.
[2024-11-12T05:11:26.661+0000] {taskinstance.py:1206} INFO - Marking task as UP_FOR_RETRY. dag_id=dbt_stock_analysis_dag, task_id=dbt_run, run_id=manual__2024-11-12T05:11:25.250277+00:00, execution_date=20241112T051125, start_date=20241112T051126, end_date=20241112T051126
[2024-11-12T05:11:26.679+0000] {standard_task_runner.py:110} ERROR - Failed to execute job 170 for task dbt_run (Bash command failed. The command returned a non-zero exit code 127.; 307)
[2024-11-12T05:11:26.709+0000] {local_task_job_runner.py:240} INFO - Task exited with return code 1
[2024-11-12T05:11:26.734+0000] {taskinstance.py:3498} INFO - 0 downstream tasks scheduled from follow-on schedule check
[2024-11-12T05:11:26.739+0000] {local_task_job_runner.py:222} INFO - ::endgroup::
