[2024-10-29T05:07:30.165+0000] {local_task_job_runner.py:120} INFO - ::group::Pre task execution logs
[2024-10-29T05:07:30.258+0000] {taskinstance.py:2076} INFO - Dependencies all met for dep_context=non-requeueable deps ti=<TaskInstance: SnowflakeTableCreation.create_table scheduled__2024-10-24T06:00:00+00:00 [queued]>
[2024-10-29T05:07:30.280+0000] {taskinstance.py:2076} INFO - Dependencies all met for dep_context=requeueable deps ti=<TaskInstance: SnowflakeTableCreation.create_table scheduled__2024-10-24T06:00:00+00:00 [queued]>
[2024-10-29T05:07:30.282+0000] {taskinstance.py:2306} INFO - Starting attempt 1 of 1
[2024-10-29T05:07:30.322+0000] {taskinstance.py:2330} INFO - Executing <Task(_PythonDecoratedOperator): create_table> on 2024-10-24 06:00:00+00:00
[2024-10-29T05:07:30.346+0000] {logging_mixin.py:188} WARNING - /home/***/.local/lib/python3.12/site-packages/***/task/task_runner/standard_task_runner.py:61 DeprecationWarning: This process (pid=221) is multi-threaded, use of fork() may lead to deadlocks in the child.
[2024-10-29T05:07:30.348+0000] {standard_task_runner.py:63} INFO - Started process 248 to run task
[2024-10-29T05:07:30.344+0000] {standard_task_runner.py:90} INFO - Running: ['***', 'tasks', 'run', 'SnowflakeTableCreation', 'create_table', 'scheduled__2024-10-24T06:00:00+00:00', '--job-id', '33', '--raw', '--subdir', 'DAGS_FOLDER/SnowflakeTableCreation.py', '--cfg-path', '/tmp/tmpprsgof6e']
[2024-10-29T05:07:30.350+0000] {standard_task_runner.py:91} INFO - Job 33: Subtask create_table
[2024-10-29T05:07:30.523+0000] {task_command.py:426} INFO - Running <TaskInstance: SnowflakeTableCreation.create_table scheduled__2024-10-24T06:00:00+00:00 [running]> on host 4a25c42f06c7
[2024-10-29T05:07:30.865+0000] {taskinstance.py:2648} INFO - Exporting env vars: AIRFLOW_CTX_DAG_OWNER='***' AIRFLOW_CTX_DAG_ID='SnowflakeTableCreation' AIRFLOW_CTX_TASK_ID='create_table' AIRFLOW_CTX_EXECUTION_DATE='2024-10-24T06:00:00+00:00' AIRFLOW_CTX_TRY_NUMBER='1' AIRFLOW_CTX_DAG_RUN_ID='scheduled__2024-10-24T06:00:00+00:00'
[2024-10-29T05:07:30.875+0000] {taskinstance.py:430} INFO - ::endgroup::
[2024-10-29T05:07:30.908+0000] {base.py:84} INFO - Using connection ID 'snowflake_conn' for task execution.
[2024-10-29T05:07:30.910+0000] {connection.py:399} INFO - Snowflake Connector for Python Version: 3.10.0, Python Version: 3.12.3, Platform: Linux-5.15.153.1-microsoft-standard-WSL2-x86_64-with-glibc2.36
[2024-10-29T05:07:30.912+0000] {connection.py:1239} INFO - This connection is in OCSP Fail Open Mode. TLS Certificates would be checked for validity and revocation status. Any other Certificate Revocation related exceptions or OCSP Responder failures would be disregarded in favor of connectivity.
[2024-10-29T05:07:34.574+0000] {taskinstance.py:441} INFO - ::group::Post task execution logs
[2024-10-29T05:07:34.575+0000] {taskinstance.py:2905} ERROR - Task failed with exception
Traceback (most recent call last):
  File "/home/airflow/.local/lib/python3.12/site-packages/airflow/models/taskinstance.py", line 465, in _execute_task
    result = _execute_callable(context=context, **execute_callable_kwargs)
             ^^^^^^^^^^^^^^^^^^^^^^^^^^^^^^^^^^^^^^^^^^^^^^^^^^^^^^^^^^^^^
  File "/home/airflow/.local/lib/python3.12/site-packages/airflow/models/taskinstance.py", line 432, in _execute_callable
    return execute_callable(context=context, **execute_callable_kwargs)
           ^^^^^^^^^^^^^^^^^^^^^^^^^^^^^^^^^^^^^^^^^^^^^^^^^^^^^^^^^^^^
  File "/home/airflow/.local/lib/python3.12/site-packages/airflow/models/baseoperator.py", line 400, in wrapper
    return func(self, *args, **kwargs)
           ^^^^^^^^^^^^^^^^^^^^^^^^^^^
  File "/home/airflow/.local/lib/python3.12/site-packages/airflow/decorators/base.py", line 265, in execute
    return_value = super().execute(context)
                   ^^^^^^^^^^^^^^^^^^^^^^^^
  File "/home/airflow/.local/lib/python3.12/site-packages/airflow/models/baseoperator.py", line 400, in wrapper
    return func(self, *args, **kwargs)
           ^^^^^^^^^^^^^^^^^^^^^^^^^^^
  File "/home/airflow/.local/lib/python3.12/site-packages/airflow/operators/python.py", line 235, in execute
    return_value = self.execute_callable()
                   ^^^^^^^^^^^^^^^^^^^^^^^
  File "/home/airflow/.local/lib/python3.12/site-packages/airflow/operators/python.py", line 252, in execute_callable
    return self.python_callable(*self.op_args, **self.op_kwargs)
           ^^^^^^^^^^^^^^^^^^^^^^^^^^^^^^^^^^^^^^^^^^^^^^^^^^^^^
  File "/opt/airflow/dags/SnowflakeTableCreation.py", line 17, in create_table
    conn = return_snowflake_conn()
           ^^^^^^^^^^^^^^^^^^^^^^^
  File "/opt/airflow/dags/SnowflakeTableCreation.py", line 11, in return_snowflake_conn
    conn = hook.get_conn()
           ^^^^^^^^^^^^^^^
  File "/home/airflow/.local/lib/python3.12/site-packages/airflow/providers/snowflake/hooks/snowflake.py", line 287, in get_conn
    conn = connector.connect(**conn_config)
           ^^^^^^^^^^^^^^^^^^^^^^^^^^^^^^^^
  File "/home/airflow/.local/lib/python3.12/site-packages/snowflake/connector/__init__.py", line 55, in Connect
    return SnowflakeConnection(**kwargs)
           ^^^^^^^^^^^^^^^^^^^^^^^^^^^^^
  File "/home/airflow/.local/lib/python3.12/site-packages/snowflake/connector/connection.py", line 442, in __init__
    self.connect(**kwargs)
  File "/home/airflow/.local/lib/python3.12/site-packages/snowflake/connector/connection.py", line 745, in connect
    self.__open_connection()
  File "/home/airflow/.local/lib/python3.12/site-packages/snowflake/connector/connection.py", line 1073, in __open_connection
    self.authenticate_with_retry(self.auth_class)
  File "/home/airflow/.local/lib/python3.12/site-packages/snowflake/connector/connection.py", line 1345, in authenticate_with_retry
    self._authenticate(auth_instance)
  File "/home/airflow/.local/lib/python3.12/site-packages/snowflake/connector/connection.py", line 1373, in _authenticate
    auth.authenticate(
  File "/home/airflow/.local/lib/python3.12/site-packages/snowflake/connector/auth/_auth.py", line 401, in authenticate
    Error.errorhandler_wrapper(
  File "/home/airflow/.local/lib/python3.12/site-packages/snowflake/connector/errors.py", line 290, in errorhandler_wrapper
    handed_over = Error.hand_to_other_handler(
                  ^^^^^^^^^^^^^^^^^^^^^^^^^^^^
  File "/home/airflow/.local/lib/python3.12/site-packages/snowflake/connector/errors.py", line 348, in hand_to_other_handler
    connection.errorhandler(connection, cursor, error_class, error_value)
  File "/home/airflow/.local/lib/python3.12/site-packages/snowflake/connector/errors.py", line 221, in default_errorhandler
    raise error_class(
snowflake.connector.errors.DatabaseError: 250001 (08001): None: Failed to connect to DB: JEB75478.snowflakecomputing.com:443. Your user account has been temporarily locked due to too many failed attempts. Try again after 15 minutes or contact your account administrator for assistance. For more information about this error, go to https://community.snowflake.com/s/error-your-user-login-has-been-locked.
[2024-10-29T05:07:34.589+0000] {taskinstance.py:1206} INFO - Marking task as FAILED. dag_id=SnowflakeTableCreation, task_id=create_table, run_id=scheduled__2024-10-24T06:00:00+00:00, execution_date=20241024T060000, start_date=20241029T050730, end_date=20241029T050734
[2024-10-29T05:07:34.609+0000] {standard_task_runner.py:110} ERROR - Failed to execute job 33 for task create_table (250001 (08001): None: Failed to connect to DB: JEB75478.snowflakecomputing.com:443. Your user account has been temporarily locked due to too many failed attempts. Try again after 15 minutes or contact your account administrator for assistance. For more information about this error, go to https://community.snowflake.com/s/error-your-user-login-has-been-locked.; 248)
[2024-10-29T05:07:34.651+0000] {local_task_job_runner.py:240} INFO - Task exited with return code 1
[2024-10-29T05:07:34.681+0000] {taskinstance.py:3498} INFO - 0 downstream tasks scheduled from follow-on schedule check
[2024-10-29T05:07:34.689+0000] {local_task_job_runner.py:222} INFO - ::endgroup::
