[2024-11-12T04:52:39.089+0000] {local_task_job_runner.py:120} INFO - ::group::Pre task execution logs
[2024-11-12T04:52:39.169+0000] {taskinstance.py:2076} INFO - Dependencies all met for dep_context=non-requeueable deps ti=<TaskInstance: BuildELT_dbt.dbt_run manual__2024-11-12T04:52:38.509433+00:00 [queued]>
[2024-11-12T04:52:39.201+0000] {taskinstance.py:2076} INFO - Dependencies all met for dep_context=requeueable deps ti=<TaskInstance: BuildELT_dbt.dbt_run manual__2024-11-12T04:52:38.509433+00:00 [queued]>
[2024-11-12T04:52:39.204+0000] {taskinstance.py:2306} INFO - Starting attempt 1 of 1
[2024-11-12T04:52:39.242+0000] {taskinstance.py:2330} INFO - Executing <Task(BashOperator): dbt_run> on 2024-11-12 04:52:38.509433+00:00
[2024-11-12T04:52:39.252+0000] {standard_task_runner.py:90} INFO - Running: ['***', 'tasks', 'run', 'BuildELT_dbt', 'dbt_run', 'manual__2024-11-12T04:52:38.509433+00:00', '--job-id', '162', '--raw', '--subdir', 'DAGS_FOLDER/build_elt_with_dbt.py', '--cfg-path', '/tmp/tmp9n3e6g6f']
[2024-11-12T04:52:39.258+0000] {standard_task_runner.py:91} INFO - Job 162: Subtask dbt_run
[2024-11-12T04:52:39.264+0000] {logging_mixin.py:188} WARNING - /home/***/.local/lib/python3.12/site-packages/***/task/task_runner/standard_task_runner.py:61 DeprecationWarning: This process (pid=303) is multi-threaded, use of fork() may lead to deadlocks in the child.
[2024-11-12T04:52:39.265+0000] {standard_task_runner.py:63} INFO - Started process 304 to run task
[2024-11-12T04:52:39.360+0000] {task_command.py:426} INFO - Running <TaskInstance: BuildELT_dbt.dbt_run manual__2024-11-12T04:52:38.509433+00:00 [running]> on host f3d2ff879b5a
[2024-11-12T04:52:39.569+0000] {taskinstance.py:2648} INFO - Exporting env vars: AIRFLOW_CTX_DAG_OWNER='***' AIRFLOW_CTX_DAG_ID='BuildELT_dbt' AIRFLOW_CTX_TASK_ID='dbt_run' AIRFLOW_CTX_EXECUTION_DATE='2024-11-12T04:52:38.509433+00:00' AIRFLOW_CTX_TRY_NUMBER='1' AIRFLOW_CTX_DAG_RUN_ID='manual__2024-11-12T04:52:38.509433+00:00'
[2024-11-12T04:52:39.570+0000] {taskinstance.py:430} INFO - ::endgroup::
[2024-11-12T04:52:39.586+0000] {subprocess.py:63} INFO - Tmp dir root location: /tmp
[2024-11-12T04:52:39.587+0000] {subprocess.py:75} INFO - Running command: ['/usr/bin/bash', '-c', '/home/***/.local/bin/dbt run --profiles-dir /opt/***/dbt --project-dir /opt/***/dbt']
[2024-11-12T04:52:39.598+0000] {subprocess.py:86} INFO - Output:
[2024-11-12T04:52:39.599+0000] {subprocess.py:93} INFO - /usr/bin/bash: line 1: /home/***/.local/bin/dbt: No such file or directory
[2024-11-12T04:52:39.600+0000] {subprocess.py:97} INFO - Command exited with return code 127
[2024-11-12T04:52:39.601+0000] {taskinstance.py:441} INFO - ::group::Post task execution logs
[2024-11-12T04:52:39.615+0000] {taskinstance.py:2905} ERROR - Task failed with exception
Traceback (most recent call last):
  File "/home/airflow/.local/lib/python3.12/site-packages/airflow/models/taskinstance.py", line 465, in _execute_task
    result = _execute_callable(context=context, **execute_callable_kwargs)
             ^^^^^^^^^^^^^^^^^^^^^^^^^^^^^^^^^^^^^^^^^^^^^^^^^^^^^^^^^^^^^
  File "/home/airflow/.local/lib/python3.12/site-packages/airflow/models/taskinstance.py", line 432, in _execute_callable
    return execute_callable(context=context, **execute_callable_kwargs)
           ^^^^^^^^^^^^^^^^^^^^^^^^^^^^^^^^^^^^^^^^^^^^^^^^^^^^^^^^^^^^
  File "/home/airflow/.local/lib/python3.12/site-packages/airflow/models/baseoperator.py", line 400, in wrapper
    return func(self, *args, **kwargs)
           ^^^^^^^^^^^^^^^^^^^^^^^^^^^
  File "/home/airflow/.local/lib/python3.12/site-packages/airflow/operators/bash.py", line 243, in execute
    raise AirflowException(
airflow.exceptions.AirflowException: Bash command failed. The command returned a non-zero exit code 127.
[2024-11-12T04:52:39.620+0000] {taskinstance.py:1206} INFO - Marking task as FAILED. dag_id=BuildELT_dbt, task_id=dbt_run, run_id=manual__2024-11-12T04:52:38.509433+00:00, execution_date=20241112T045238, start_date=20241112T045239, end_date=20241112T045239
[2024-11-12T04:52:39.643+0000] {standard_task_runner.py:110} ERROR - Failed to execute job 162 for task dbt_run (Bash command failed. The command returned a non-zero exit code 127.; 304)
[2024-11-12T04:52:39.683+0000] {local_task_job_runner.py:240} INFO - Task exited with return code 1
[2024-11-12T04:52:39.717+0000] {taskinstance.py:3498} INFO - 0 downstream tasks scheduled from follow-on schedule check
[2024-11-12T04:52:39.728+0000] {local_task_job_runner.py:222} INFO - ::endgroup::
