[2024-11-12T19:50:39.787+0000] {local_task_job_runner.py:120} INFO - ::group::Pre task execution logs
[2024-11-12T19:50:39.844+0000] {taskinstance.py:2076} INFO - Dependencies all met for dep_context=non-requeueable deps ti=<TaskInstance: dbt_stock_analysis_dag.dbt_run manual__2024-11-12T19:50:39.063867+00:00 [queued]>
[2024-11-12T19:50:39.864+0000] {taskinstance.py:2076} INFO - Dependencies all met for dep_context=requeueable deps ti=<TaskInstance: dbt_stock_analysis_dag.dbt_run manual__2024-11-12T19:50:39.063867+00:00 [queued]>
[2024-11-12T19:50:39.868+0000] {taskinstance.py:2306} INFO - Starting attempt 1 of 2
[2024-11-12T19:50:39.893+0000] {taskinstance.py:2330} INFO - Executing <Task(BashOperator): dbt_run> on 2024-11-12 19:50:39.063867+00:00
[2024-11-12T19:50:39.904+0000] {standard_task_runner.py:90} INFO - Running: ['***', 'tasks', 'run', 'dbt_stock_analysis_dag', 'dbt_run', 'manual__2024-11-12T19:50:39.063867+00:00', '--job-id', '184', '--raw', '--subdir', 'DAGS_FOLDER/DAG for dbt.py', '--cfg-path', '/tmp/tmpapxd_jls']
[2024-11-12T19:50:39.907+0000] {standard_task_runner.py:91} INFO - Job 184: Subtask dbt_run
[2024-11-12T19:50:39.907+0000] {logging_mixin.py:188} WARNING - /home/***/.local/lib/python3.12/site-packages/***/task/task_runner/standard_task_runner.py:61 DeprecationWarning: This process (pid=394) is multi-threaded, use of fork() may lead to deadlocks in the child.
[2024-11-12T19:50:39.908+0000] {standard_task_runner.py:63} INFO - Started process 395 to run task
[2024-11-12T19:50:39.964+0000] {task_command.py:426} INFO - Running <TaskInstance: dbt_stock_analysis_dag.dbt_run manual__2024-11-12T19:50:39.063867+00:00 [running]> on host 16d7368eac06
[2024-11-12T19:50:40.164+0000] {taskinstance.py:2648} INFO - Exporting env vars: AIRFLOW_CTX_DAG_OWNER='Utkarsh Tripathi' AIRFLOW_CTX_DAG_ID='dbt_stock_analysis_dag' AIRFLOW_CTX_TASK_ID='dbt_run' AIRFLOW_CTX_EXECUTION_DATE='2024-11-12T19:50:39.063867+00:00' AIRFLOW_CTX_TRY_NUMBER='1' AIRFLOW_CTX_DAG_RUN_ID='manual__2024-11-12T19:50:39.063867+00:00'
[2024-11-12T19:50:40.166+0000] {taskinstance.py:430} INFO - ::endgroup::
[2024-11-12T19:50:40.183+0000] {subprocess.py:63} INFO - Tmp dir root location: /tmp
[2024-11-12T19:50:40.184+0000] {subprocess.py:75} INFO - Running command: ['/usr/bin/bash', '-c', '/home/***/.local/bin/dbt run --profiles-dir /opt/***/dbt --project-dir /opt/***/dbt']
[2024-11-12T19:50:40.192+0000] {subprocess.py:86} INFO - Output:
[2024-11-12T19:50:40.193+0000] {subprocess.py:93} INFO - /usr/bin/bash: line 1: /home/***/.local/bin/dbt: No such file or directory
[2024-11-12T19:50:40.194+0000] {subprocess.py:97} INFO - Command exited with return code 127
[2024-11-12T19:50:40.195+0000] {taskinstance.py:441} INFO - ::group::Post task execution logs
[2024-11-12T19:50:40.208+0000] {taskinstance.py:2905} ERROR - Task failed with exception
Traceback (most recent call last):
  File "/home/airflow/.local/lib/python3.12/site-packages/airflow/models/taskinstance.py", line 465, in _execute_task
    result = _execute_callable(context=context, **execute_callable_kwargs)
             ^^^^^^^^^^^^^^^^^^^^^^^^^^^^^^^^^^^^^^^^^^^^^^^^^^^^^^^^^^^^^
  File "/home/airflow/.local/lib/python3.12/site-packages/airflow/models/taskinstance.py", line 432, in _execute_callable
    return execute_callable(context=context, **execute_callable_kwargs)
           ^^^^^^^^^^^^^^^^^^^^^^^^^^^^^^^^^^^^^^^^^^^^^^^^^^^^^^^^^^^^
  File "/home/airflow/.local/lib/python3.12/site-packages/airflow/models/baseoperator.py", line 400, in wrapper
    return func(self, *args, **kwargs)
           ^^^^^^^^^^^^^^^^^^^^^^^^^^^
  File "/home/airflow/.local/lib/python3.12/site-packages/airflow/operators/bash.py", line 243, in execute
    raise AirflowException(
airflow.exceptions.AirflowException: Bash command failed. The command returned a non-zero exit code 127.
[2024-11-12T19:50:40.216+0000] {taskinstance.py:1206} INFO - Marking task as UP_FOR_RETRY. dag_id=dbt_stock_analysis_dag, task_id=dbt_run, run_id=manual__2024-11-12T19:50:39.063867+00:00, execution_date=20241112T195039, start_date=20241112T195039, end_date=20241112T195040
[2024-11-12T19:50:40.233+0000] {standard_task_runner.py:110} ERROR - Failed to execute job 184 for task dbt_run (Bash command failed. The command returned a non-zero exit code 127.; 395)
[2024-11-12T19:50:40.243+0000] {local_task_job_runner.py:240} INFO - Task exited with return code 1
[2024-11-12T19:50:40.271+0000] {taskinstance.py:3498} INFO - 0 downstream tasks scheduled from follow-on schedule check
[2024-11-12T19:50:40.276+0000] {local_task_job_runner.py:222} INFO - ::endgroup::
