[2024-10-24T02:47:06.195+0000] {local_task_job_runner.py:120} INFO - ::group::Pre task execution logs
[2024-10-24T02:47:06.226+0000] {taskinstance.py:2076} INFO - Dependencies all met for dep_context=non-requeueable deps ti=<TaskInstance: SessionToSnowflake.create_table manual__2024-10-24T02:47:04.112520+00:00 [queued]>
[2024-10-24T02:47:06.237+0000] {taskinstance.py:2076} INFO - Dependencies all met for dep_context=requeueable deps ti=<TaskInstance: SessionToSnowflake.create_table manual__2024-10-24T02:47:04.112520+00:00 [queued]>
[2024-10-24T02:47:06.240+0000] {taskinstance.py:2306} INFO - Starting attempt 1 of 1
[2024-10-24T02:47:06.260+0000] {taskinstance.py:2330} INFO - Executing <Task(_PythonDecoratedOperator): create_table> on 2024-10-24 02:47:04.112520+00:00
[2024-10-24T02:47:06.268+0000] {standard_task_runner.py:90} INFO - Running: ['***', 'tasks', 'run', 'SessionToSnowflake', 'create_table', 'manual__2024-10-24T02:47:04.112520+00:00', '--job-id', '3', '--raw', '--subdir', 'DAGS_FOLDER/SessionToSnowflake.py', '--cfg-path', '/tmp/tmptvpm_47p']
[2024-10-24T02:47:06.270+0000] {standard_task_runner.py:91} INFO - Job 3: Subtask create_table
[2024-10-24T02:47:06.272+0000] {logging_mixin.py:188} WARNING - /home/***/.local/lib/python3.12/site-packages/***/task/task_runner/standard_task_runner.py:61 DeprecationWarning: This process (pid=322) is multi-threaded, use of fork() may lead to deadlocks in the child.
[2024-10-24T02:47:06.273+0000] {standard_task_runner.py:63} INFO - Started process 325 to run task
[2024-10-24T02:47:06.318+0000] {task_command.py:426} INFO - Running <TaskInstance: SessionToSnowflake.create_table manual__2024-10-24T02:47:04.112520+00:00 [running]> on host 4a25c42f06c7
[2024-10-24T02:47:06.398+0000] {taskinstance.py:2648} INFO - Exporting env vars: AIRFLOW_CTX_DAG_OWNER='***' AIRFLOW_CTX_DAG_ID='SessionToSnowflake' AIRFLOW_CTX_TASK_ID='create_table' AIRFLOW_CTX_EXECUTION_DATE='2024-10-24T02:47:04.112520+00:00' AIRFLOW_CTX_TRY_NUMBER='1' AIRFLOW_CTX_DAG_RUN_ID='manual__2024-10-24T02:47:04.112520+00:00'
[2024-10-24T02:47:06.401+0000] {taskinstance.py:430} INFO - ::endgroup::
[2024-10-24T02:47:06.408+0000] {taskinstance.py:441} INFO - ::group::Post task execution logs
[2024-10-24T02:47:06.416+0000] {taskinstance.py:2905} ERROR - Task failed with exception
Traceback (most recent call last):
  File "/home/airflow/.local/lib/python3.12/site-packages/airflow/models/taskinstance.py", line 465, in _execute_task
    result = _execute_callable(context=context, **execute_callable_kwargs)
             ^^^^^^^^^^^^^^^^^^^^^^^^^^^^^^^^^^^^^^^^^^^^^^^^^^^^^^^^^^^^^
  File "/home/airflow/.local/lib/python3.12/site-packages/airflow/models/taskinstance.py", line 432, in _execute_callable
    return execute_callable(context=context, **execute_callable_kwargs)
           ^^^^^^^^^^^^^^^^^^^^^^^^^^^^^^^^^^^^^^^^^^^^^^^^^^^^^^^^^^^^
  File "/home/airflow/.local/lib/python3.12/site-packages/airflow/models/baseoperator.py", line 400, in wrapper
    return func(self, *args, **kwargs)
           ^^^^^^^^^^^^^^^^^^^^^^^^^^^
  File "/home/airflow/.local/lib/python3.12/site-packages/airflow/decorators/base.py", line 265, in execute
    return_value = super().execute(context)
                   ^^^^^^^^^^^^^^^^^^^^^^^^
  File "/home/airflow/.local/lib/python3.12/site-packages/airflow/models/baseoperator.py", line 400, in wrapper
    return func(self, *args, **kwargs)
           ^^^^^^^^^^^^^^^^^^^^^^^^^^^
  File "/home/airflow/.local/lib/python3.12/site-packages/airflow/operators/python.py", line 235, in execute
    return_value = self.execute_callable()
                   ^^^^^^^^^^^^^^^^^^^^^^^
  File "/home/airflow/.local/lib/python3.12/site-packages/airflow/operators/python.py", line 252, in execute_callable
    return self.python_callable(*self.op_args, **self.op_kwargs)
           ^^^^^^^^^^^^^^^^^^^^^^^^^^^^^^^^^^^^^^^^^^^^^^^^^^^^^
  File "/opt/airflow/dags/SessionToSnowflake.py", line 17, in create_table
    conn = return_snowflake_conn()
           ^^^^^^^^^^^^^^^^^^^^^^^
  File "/opt/airflow/dags/SessionToSnowflake.py", line 11, in return_snowflake_conn
    conn = hook.get_conn()
           ^^^^^^^^^^^^^^^
  File "/home/airflow/.local/lib/python3.12/site-packages/airflow/providers/snowflake/hooks/snowflake.py", line 286, in get_conn
    conn_config = self._get_conn_params()
                  ^^^^^^^^^^^^^^^^^^^^^^^
  File "/home/airflow/.local/lib/python3.12/site-packages/airflow/providers/snowflake/hooks/snowflake.py", line 185, in _get_conn_params
    conn = self.get_connection(self.snowflake_conn_id)  # type: ignore[attr-defined]
           ^^^^^^^^^^^^^^^^^^^^^^^^^^^^^^^^^^^^^^^^^^^
  File "/home/airflow/.local/lib/python3.12/site-packages/airflow/hooks/base.py", line 83, in get_connection
    conn = Connection.get_connection_from_secrets(conn_id)
           ^^^^^^^^^^^^^^^^^^^^^^^^^^^^^^^^^^^^^^^^^^^^^^^
  File "/home/airflow/.local/lib/python3.12/site-packages/airflow/models/connection.py", line 519, in get_connection_from_secrets
    raise AirflowNotFoundException(f"The conn_id `{conn_id}` isn't defined")
airflow.exceptions.AirflowNotFoundException: The conn_id `snowflake_conn` isn't defined
[2024-10-24T02:47:06.425+0000] {taskinstance.py:1206} INFO - Marking task as FAILED. dag_id=SessionToSnowflake, task_id=create_table, run_id=manual__2024-10-24T02:47:04.112520+00:00, execution_date=20241024T024704, start_date=20241024T024706, end_date=20241024T024706
[2024-10-24T02:47:06.440+0000] {standard_task_runner.py:110} ERROR - Failed to execute job 3 for task create_table (The conn_id `snowflake_conn` isn't defined; 325)
[2024-10-24T02:47:06.489+0000] {local_task_job_runner.py:240} INFO - Task exited with return code 1
[2024-10-24T02:47:06.514+0000] {taskinstance.py:3498} INFO - 0 downstream tasks scheduled from follow-on schedule check
[2024-10-24T02:47:06.539+0000] {local_task_job_runner.py:222} INFO - ::endgroup::
